Workbook
Name AMALFIPOOL: 'AMALFI POOL'!$A$1
Name ARRIVAL: 'ARRIVAL (RECEPTION)'!$A$1
Name BOHL02: 'BOH L02'!$A$1
Name BOHL03: 'BOH L03'!$A$1
Name BOHL04: 'BOH L04'!$A$1
Name CAFEMAUDE: 'CAFE MAUDE'!$A$1
Name EMBERS: EMBERS!$A$1
Name FIFTH: '5th Floor'!$A$1
Name FUNICULAR: FUNICULAR!$A$1
Name GUESTROOM: 'Guest Room '!$A$1
Name KITCHEN: 'Kitchen and Storage'!$A$2
Name LEVELS: 'LEVEL 4, 5 & 6'!$A$1
Name MENU: MENU!$E$3
Name MICEAREA: 'MICE AREA'!$A$1
Name RECREATION: 'RECREATION DRIFT POOLBAR & GRIL'!$A$1
Name ROOMNOCLUSTERS: 'ROOM NO & CLUSTERS'!$A$1
Name SIXTH: '6th Floor'!$A$1
Name SPAFITNESS: 'SPA & Fitness'!$A$1
Name STANDALONE: 'Stand Alone Building '!$A$1

Sheet MENU
C3: TABLE OF CONTENT
C5: Zone | D5: Total Snag Raised | E5: Total Snag Open | F5: Total Snag Closed
C6: BOH L00 | D6: =BOHL00[[#Totals],[Column8]] -> 603 | E6: =BOHL00[[#Totals],[Column9]] -> 224 | F6: =BOHL00[[#Totals],[Column10]] -> 379
C7: BOH L01 | D7: =BOHL01[[#Totals],[Column8]] -> 4079 | E7: =BOHL01[[#Totals],[Column9]] -> 1614 | F7: =BOHL01[[#Totals],[Column10]] -> 2580
C8: BOH L02 | D8: =Table25[[#Totals],[Column8]] -> 0 | E8: =Table25[[#Totals],[Column9]] -> 0 | F8: =Table25[[#Totals],[Column10]] -> 0
C9: BOH L03 | D9: ='BOH L03'!K45 -> 0 | E9: ='BOH L03'!L45 -> 0 | F9: ='BOH L03'!M45 -> 0
C10: BOH L04 | D10: =Table27[[#Totals],[Column8]] -> 0 | E10: =Table27[[#Totals],[Column9]] -> 0 | F10: =Table27[[#Totals],[Column10]] -> 0
C11: 5th Floor | D11: ='5th Floor'!L71 -> 0 | E11: ='5th Floor'!M71 -> 0 | F11: ='5th Floor'!N71 -> 0
C12: 6th Floor | D12: ='6th Floor'!L28 -> 0 | E12: ='6th Floor'!M28 -> 0 | F12: ='6th Floor'!N28 -> 0
C13: LEVEL 4, 5 & 6 | D13: ='LEVEL 4, 5 & 6'!M22 -> 0 | E13: ='LEVEL 4, 5 & 6'!N22 -> 0 | F13: ='LEVEL 4, 5 & 6'!O22 -> 0
C14: CAFE MAUDE | D14: ='CAFE MAUDE'!M19 -> 0 | E14: ='CAFE MAUDE'!N19 -> 0 | F14: ='CAFE MAUDE'!O19 -> 0
C15: EMBERS
C16: AMALFI POOL
C17: RECREATION DRIFT POOLBAR & GRILL
C18: SPA & Fitness | D18: ='SPA & Fitness'!M88 -> 0 | E18: ='SPA & Fitness'!N88 -> 0 | F18: ='SPA & Fitness'!O88 -> 0
C19: MICE AREA | D19: ='MICE AREA'!M34 -> 0 | E19: ='MICE AREA'!N34 -> 0 | F19: ='MICE AREA'!O34 -> 0
C20: ARRIVAL (RECEPTION)
C21: FUNICULAR
C22: Stand Alone Building | D22: ='Stand Alone Building '!M141 -> 0 | E22: ='Stand Alone Building '!N141 -> 0 | F22: ='Stand Alone Building '!O141 -> 0
C23: Guest Room | D23: ='Guest Room '!J90 -> 17485 | E23: ='Guest Room '!K90 -> 7645 | F23: ='Guest Room '!L90 -> 9840
C24: ROOM NO & CLUSTERS
C25: Kitchen and Storage
D404: Stage 1a Completion of Operator Inspection (Pre FFE) | H404: Stage 1a Completion of Operator Inspection (Pre FFE)
H405: TOTAL | I405: =I406+I407 -> 382
H406: completed | I406: ='BOH L01'!P73 -> 201
D407: TOTAL | E407: =E408+E409 -> 77 | H407: pending | I407: ='BOH L01'!P74 -> 181
D408: completed | E408: ='BOH L00'!P55 -> 52
D409: pending | E409: ='BOH L00'!P56 -> 25
H410: Stage 1b Completion of De-Snagging and close out operator Comments/Deep Cleaning
D411: Stage 1b Completion of De-Snagging and close out operator Comments/Deep Cleaning | H411: TOTAL | I411: =I412+I413 -> 382
H412: completed | I412: ='BOH L01'!S73 -> 165
H413: pending | I413: ='BOH L01'!S74 -> 217
D414: TOTAL | E414: =E415+E416 -> 77
D415: completed | E415: ='BOH L00'!S55 -> 21
D416: pending | E416: ='BOH L00'!S56 -> 56

Sheet BOH MOUND
B2: MENU
B5: SNAGGED DATE | C5: SNAGGED BY | D5: ROOM NO. | E5: ROOM NAME | F5: Stage 1a Completion of Operator Inspection (Pre FFE) | G5: Stage 1b Completion of De-Snagging and close out operator Comments/Deep Cleaning | H5: Completion of FF&E installation | I5: Stage 2a Completion of Operator Inspection (Post FFE) | J5: Stage 2b Completion of De-Snagging /Sparkle Cleaning and handover | K5: Total Snag Raised | L5: Total Snag Open | M5: Total Snag Closed | N5: Stage 1a Completion of Operator Inspection (Pre FFE) | P5: Stage 1b Completion of De-Snagging and close out operator Comments/Deep Cleaning | S5: list
D6: Column1 | E6: Column2 | F6: Column3 | G6: Column4 | H6: Column5 | I6: Column6 | J6: Column7 | K6: Column8 | L6: Column9 | M6: Column10
D7: 00-001 | E7: CART PARKING AREA | F7: FALSE | G7: FALSE | H7: FALSE | I7: FALSE | J7: FALSE | L7: =K7-M7 -> 0 | S7: Arvind
D8: 00-001a | E8: CART PARKING AREA | F8: FALSE | G8: FALSE | H8: FALSE | I8: FALSE | J8: FALSE | L8: =K8-M8 -> 0 | N8: TOTAL | O8: =O9+O10 -> 77 | S8: Thayalaraj
B9: 46051 | C9: Thayalaraj | D9: 00-002 | E9: CLEAN LINEN & HOUSEKEEPING STORAGE | F9: TRUE | G9: TRUE | H9: FALSE | I9: FALSE | J9: FALSE | K9: 9 | L9: =K9-M9 -> 3 | M9: 6 | N9: completed | O9: =COUNTIFS(F7:F83,TRUE) -> 47 | P9: TOTAL | Q9: =Q10+Q11 -> 77 | S9: Abdulrahman
B10: 46051 | C10: Thayalaraj | D10: 00-003 | E10: MAIN CIRCULATION | F10: TRUE | G10: FALSE | H10: FALSE | I10: FALSE | J10: FALSE | K10: 3 | L10: =K10-M10 -> 0 | M10: 3 | N10: pending | O10: =COUNTIFS(F7:F83,FALSE) -> 30 | P10: completed | Q10: =COUNTIFS(G8:G84,TRUE) -> 21 | S10: Naseer
B11: 46051 | C11: Thayalaraj | D11: 00-004 | E11: HOUSEKEEPING & SERVICE PANTRY | F11: TRUE | G11: TRUE | H11: FALSE | I11: FALSE | J11: FALSE | K11: 13 | L11: =K11-M11 -> 7 | M11: 6 | P11: pending | Q11: =COUNTIFS(G8:G84,FALSE) -> 56 | S11: M.Adel
B12: 46051 | C12: Hafil | D12: 00-005 | E12: SERVICE CORRIDOR | F12: TRUE | G12: FALSE | H12: FALSE | I12: FALSE | J12: FALSE | K12: 5 | L12: =K12-M12 -> 3 | M12: 2 | S12: Tarik
B13: 46051 | C13: Thayalaraj | D13: 00-006 | E13: WASTE HOLDING | F13: TRUE | G13: TRUE | H13: FALSE | I13: FALSE | J13: FALSE | K13: 5 | L13: =K13-M13 -> 0 | M13: 5 | S13: Akram
B14: 46051 | C14: Hafil | D14: 00-007 | E14: W.C. | F14: TRUE | G14: FALSE | H14: FALSE | I14: FALSE | J14: FALSE | K14: 6 | L14: =K14-M14 -> 4 | M14: 2 | S14: Prasanna
B15: 46051 | C15: Hafil | D15: 00-008 | E15: DIRTY LINEN HOLDING | F15: TRUE | G15: FALSE | H15: FALSE | I15: FALSE | J15: FALSE | K15: 5 | L15: =K15-M15 -> 2 | M15: 3 | S15: Suresh
B16: 46051 | C16: Hafil | D16: 00-009 | E16: BUTLER REST AREA | F16: TRUE | G16: FALSE | H16: FALSE | I16: FALSE | J16: FALSE | K16: 1 | L16: =K16-M16 -> 0 | M16: 1 | S16: Mosab
D17: 00-010 | E17: HOTEL CIRCULATION | F17: FALSE | G17: FALSE | H17: FALSE | I17: FALSE | J17: FALSE | L17: =K17-M17 -> 0 | S17: Nawaf
D18: 00-011 | E18: GUEST LIFT LOBBY | F18: FALSE | G18: FALSE | H18: FALSE | I18: FALSE | J18: FALSE | L18: =K18-M18 -> 0 | S18: Hafil
D19: 00-012 | E19: HOTEL CIRCULATION | F19: FALSE | G19: FALSE | H19: FALSE | I19: FALSE | J19: FALSE | L19: =K19-M19 -> 0 | S19: Ibrar
D20: 00-013 | E20: GUEST STAIR - 03 | F20: FALSE | G20: FALSE | H20: FALSE | I20: FALSE | J20: FALSE | L20: =K20-M20 -> 0 | S20: Brigitta
B21: 46048 | C21: Tarik | D21: 00-014 | E21: CR ROOM | F21: TRUE | G21: FALSE | H21: FALSE | I21: FALSE | J21: FALSE | K21: 12 | L21: =K21-M21 -> 1 | M21: 11 | S21: Ahmed Abdelghany
B22: 46048 | C22: Tarik | D22: 00-015 | E22: ELECTRICAL ROOM | F22: TRUE | G22: FALSE | H22: FALSE | I22: FALSE | J22: FALSE | K22: 11 | L22: =K22-M22 -> 2 | M22: 9 | S22: Simon Gonsalves
B23: 46121 | C23: Hafil | D23: 00-016 | E23: MAIN CIRCULATION | F23: TRUE | G23: FALSE | H23: FALSE | I23: FALSE | J23: FALSE | K23: 4 | L23: =K23-M23 -> 4 | S23: Alvear Felipe
B24: 46121 | C24: Ibrar | D24: 00-017 | E24: SERVICE LIFT LOBBY | F24: TRUE | G24: FALSE | H24: FALSE | I24: FALSE | J24: FALSE | K24: 11 | L24: =K24-M24 -> 11
D25: 00-019 | E25: SERVICE STAIR - 01 | F25: FALSE | G25: FALSE | H25: FALSE | I25: FALSE | J25: FALSE | L25: =K25-M25 -> 0
B26: 46048 | C26: Ibrar | D26: 00-020 | E26: SERVICE CORRIDOR | F26: TRUE | G26: FALSE | H26: FALSE | I26: FALSE | J26: FALSE | K26: 4 | L26: =K26-M26 -> 4
B27: 46121 | C27: Ibrar | D27: 00-021 | E27: SERVICE CORRIDOR | F27: TRUE | G27: FALSE | H27: FALSE | I27: FALSE | J27: FALSE | K27: 12 | L27: =K27-M27 -> 12
D28: 00-023 | E28: CART PARKING AREA | F28: FALSE | G28: FALSE | H28: FALSE | I28: FALSE | J28: FALSE | L28: =K28-M28 -> 0
B29: 46121 | C29: Tarik | D29: 00-024 | E29: ELECTRICAL ROOM | F29: TRUE | G29: FALSE | H29: FALSE | I29: FALSE | J29: FALSE | K29: 23 | L29: =K29-M29 -> 23
B30: 46124 | C30: Ibrar | D30: 00-025 | E30: CR ROOM | F30: TRUE | G30: FALSE | H30: FALSE | I30: FALSE | J30: FALSE | K30: 13 | L30: =K30-M30 -> 13
D31: 00-027 | E31: CART PARKING AREA | F31: FALSE | G31: FALSE | H31: FALSE | I31: FALSE | J31: FALSE | L31: =K31-M31 -> 0
B32: 46051 | C32: HAFIL | D32: 00-028 | E32: MAIN CIRCULATION | F32: TRUE | G32: TRUE | H32: FALSE | I32: FALSE | J32: FALSE | K32: 6 | L32: =K32-M32 -> 0 | M32: 6
B33: 46026 | C33: Arvind | D33: 00-029 | E33: CLEAN LINEN & HOUSEKEEPING STORAGE | F33: TRUE | G33: TRUE | H33: FALSE | I33: FALSE | J33: FALSE | K33: 21 | L33: =K33-M33 -> 4 | M33: 17
B34: 46026 | C34: Arvind | D34: 00-030 | E34: HOUSEKEEPING & SERVICE PANTRY | F34: TRUE | G34: TRUE | H34: FALSE | I34: FALSE | J34: FALSE | K34: 36 | L34: =K34-M34 -> 9 | M34: 27
B35: 46048 | C35: Akram | D35: 00-031 | E35: SERVICE CORRIDOR | F35: TRUE | G35: TRUE | H35: FALSE | I35: FALSE | J35: FALSE | K35: 7 | L35: =K35-M35 -> 0 | M35: 7
B36: 46027 | C36: Tarik | D36: 00-032 | E36: Waste holding | F36: TRUE | G36: TRUE | H36: FALSE | I36: FALSE | J36: FALSE | K36: 16 | L36: =K36-M36 -> 0 | M36: 16
B37: 46026 | C37: Arvind | D37: 00-033 | E37: W.C. | F37: TRUE | G37: TRUE | H37: FALSE | I37: FALSE | J37: FALSE | K37: 12 | L37: =K37-M37 -> 1 | M37: 11
B38: 46027 | C38: Tarik | D38: 00-034 | E38: DIRTY LINEN HOLDING | F38: TRUE | G38: TRUE | H38: FALSE | I38: FALSE | J38: FALSE | K38: 6 | L38: =K38-M38 -> 0 | M38: 6
B39: 46027 | C39: Tarik | D39: 00-035 | E39: BUTLER REST AREA | F39: TRUE | G39: TRUE | H39: FALSE | I39: FALSE | J39: FALSE | K39: 9 | L39: =K39-M39 -> 2 | M39: 7
D40: 00-036 | E40: HOTEL CIRCULATION | F40: FALSE | G40: FALSE | H40: FALSE | I40: FALSE | J40: FALSE | L40: =K40-M40 -> 0
D41: 00-037 | E41: GUEST LIFT LOBBY | F41: FALSE | G41: FALSE | H41: FALSE | I41: FALSE | J41: FALSE | L41: =K41-M41 -> 0
D42: 00-038 | E42: HOTEL CIRCULATION | F42: FALSE | G42: FALSE | H42: FALSE | I42: FALSE | J42: FALSE | L42: =K42-M42 -> 0
D43: 00-039 | E43: GUEST STAIR - 04 | F43: FALSE | G43: FALSE | H43: FALSE | I43: FALSE | J43: FALSE | L43: =K43-M43 -> 0
...

Sheet BOH L00
B2: MENU
B16: SNAGGED DATE | C16: SNAGGED BY | D16: ROOM NO. | E16: ROOM NAME | F16: Stage 1a Completion of Operator Inspection (Pre FFE) | G16: Stage 1b Completion of De-Snagging and close out operator Comments/Deep Cleaning | H16: Completion of FF&E installation | I16: Stage 2a Completion of Operator Inspection (Post FFE) | J16: Stage 2b Completion of De-Snagging /Sparkle Cleaning and handover | K16: Total Snag Raised | L16: Total Snag Open | M16: Total Snag Closed | U16: list
D17: Column1 | E17: Column2 | F17: Column3 | G17: Column4 | H17: Column5 | I17: Column6 | J17: Column7 | K17: Column8 | L17: Column9 | M17: Column10
D18: 00-001 | E18: CART PARKING AREA | F18: FALSE | G18: FALSE | H18: FALSE | I18: FALSE | J18: FALSE | L18: =K18-M18 -> 0 | U18: Arvind
D19: 00-001a | E19: CART PARKING AREA | F19: FALSE | G19: FALSE | H19: FALSE | I19: FALSE | J19: FALSE | L19: =K19-M19 -> 0 | U19: Thayalaraj
B20: 46051 | C20: Thayalaraj | D20: 00-002 | E20: CLEAN LINEN & HOUSEKEEPING STORAGE | F20: TRUE | G20: TRUE | H20: FALSE | I20: FALSE | J20: FALSE | K20: 9 | L20: =K20-M20 -> 1 | M20: 8 | U20: Arvind
B21: 46051 | C21: Thayalaraj | D21: 00-003 | E21: MAIN CIRCULATION | F21: TRUE | G21: FALSE | H21: FALSE | I21: FALSE | J21: FALSE | K21: 6 | L21: =K21-M21 -> 0 | M21: 6 | U21: Thayalaraj
B22: 46051 | C22: Thayalaraj | D22: 00-004 | E22: HOUSEKEEPING & SERVICE PANTRY | F22: TRUE | G22: TRUE | H22: FALSE | I22: FALSE | J22: FALSE | K22: 23 | L22: =K22-M22 -> 2 | M22: 21 | U22: Abdulrahman
B23: 46051 | C23: Hafil | D23: 00-005 | E23: SERVICE CORRIDOR | F23: TRUE | G23: FALSE | H23: FALSE | I23: FALSE | J23: FALSE | K23: 5 | L23: =K23-M23 -> 1 | M23: 4 | U23: Naseer
B24: 46051 | C24: Thayalaraj | D24: 00-006 | E24: WASTE HOLDING | F24: TRUE | G24: TRUE | H24: FALSE | I24: FALSE | J24: FALSE | K24: 8 | L24: =K24-M24 -> 1 | M24: 7 | U24: M.Adel
B25: 46051 | C25: Hafil | D25: 00-007 | E25: W.C. | F25: TRUE | G25: FALSE | H25: FALSE | I25: FALSE | J25: FALSE | K25: 6 | L25: =K25-M25 -> 3 | M25: 3 | U25: Tarik
B26: 46051 | C26: Hafil | D26: 00-008 | E26: DIRTY LINEN HOLDING | F26: TRUE | G26: FALSE | H26: FALSE | I26: FALSE | J26: FALSE | K26: 5 | L26: =K26-M26 -> 0 | M26: 5 | U26: Akram
B27: 46051 | C27: Hafil | D27: 00-009 | E27: BUTLER REST AREA | F27: TRUE | G27: FALSE | H27: FALSE | I27: FALSE | J27: FALSE | K27: 1 | L27: =K27-M27 -> 0 | M27: 1 | U27: Prasanna
D28: 00-010 | E28: HOTEL CIRCULATION | F28: FALSE | G28: FALSE | H28: FALSE | I28: FALSE | J28: FALSE | L28: =K28-M28 -> 0 | U28: Suresh
D29: 00-011 | E29: GUEST LIFT LOBBY | F29: FALSE | G29: FALSE | H29: FALSE | I29: FALSE | J29: FALSE | L29: =K29-M29 -> 0 | U29: Mosab
D30: 00-012 | E30: HOTEL CIRCULATION | F30: FALSE | G30: FALSE | H30: FALSE | I30: FALSE | J30: FALSE | L30: =K30-M30 -> 0 | U30: Nawaf
D31: 00-013 | E31: GUEST STAIR - 03 | F31: FALSE | G31: FALSE | H31: FALSE | I31: FALSE | J31: FALSE | L31: =K31-M31 -> 0 | U31: Hafil
B32: 46048 | C32: Tarik | D32: 00-014 | E32: CR ROOM | F32: TRUE | G32: FALSE | H32: FALSE | I32: FALSE | J32: FALSE | K32: 12 | L32: =K32-M32 -> 1 | M32: 11 | U32: Ibrar
B33: 46048 | C33: Tarik | D33: 00-015 | E33: ELECTRICAL ROOM | F33: TRUE | G33: FALSE | H33: FALSE | I33: FALSE | J33: FALSE | K33: 12 | L33: =K33-M33 -> 3 | M33: 9 | U33: Brigitta
B34: 46121 | C34: Hafil | D34: 00-016 | E34: MAIN CIRCULATION | F34: TRUE | G34: FALSE | H34: FALSE | I34: FALSE | J34: FALSE | K34: 19 | L34: =K34-M34 -> 19 | U34: Ahmed Abdelghany
B35: 46121 | C35: Ibrar | D35: 00-017 | E35: SERVICE LIFT LOBBY | F35: TRUE | G35: FALSE | H35: FALSE | I35: FALSE | J35: FALSE | K35: 15 | L35: =K35-M35 -> 15 | U35: Simon Gonsalves
D36: 00-019 | E36: SERVICE STAIR - 01 | F36: FALSE | G36: FALSE | H36: FALSE | I36: FALSE | J36: FALSE | L36: =K36-M36 -> 0 | U36: Engineering team
B37: 46048 | C37: Ibrar | D37: 00-020 | E37: SERVICE CORRIDOR | F37: TRUE | G37: FALSE | H37: FALSE | I37: FALSE | J37: FALSE | K37: 4 | L37: =K37-M37 -> 4
B38: 46121 | C38: Ibrar | D38: 00-021 | E38: SERVICE CORRIDOR | F38: TRUE | G38: FALSE | H38: FALSE | I38: FALSE | J38: FALSE | K38: 17 | L38: =K38-M38 -> 17
D39: 00-023 | E39: CART PARKING AREA | F39: FALSE | G39: FALSE | H39: FALSE | I39: FALSE | J39: FALSE | L39: =K39-M39 -> 0
B40: 46121 | C40: Tarik | D40: 00-024 | E40: ELECTRICAL ROOM | F40: TRUE | G40: FALSE | H40: FALSE | I40: FALSE | J40: FALSE | K40: 23 | L40: =K40-M40 -> 23
B41: 46124 | C41: Ibrar | D41: 00-025 | E41: CR ROOM | F41: TRUE | G41: FALSE | H41: FALSE | I41: FALSE | J41: FALSE | K41: 13 | L41: =K41-M41 -> 13
D42: 00-027 | E42: CART PARKING AREA | F42: FALSE | G42: FALSE | H42: FALSE | I42: FALSE | J42: FALSE | L42: =K42-M42 -> 0
B43: 46051 | C43: HAFIL | D43: 00-028 | E43: MAIN CIRCULATION | F43: TRUE | G43: TRUE | H43: FALSE | I43: FALSE | J43: FALSE | K43: 6 | L43: =K43-M43 -> 0 | M43: 6
B44: 46026 | C44: Arvind | D44: 00-029 | E44: CLEAN LINEN & HOUSEKEEPING STORAGE | F44: TRUE | G44: TRUE | H44: FALSE | I44: FALSE | J44: FALSE | K44: 22 | L44: =K44-M44 -> 2 | M44: 20
B45: 46026 | C45: Arvind | D45: 00-030 | E45: HOUSEKEEPING & SERVICE PANTRY | F45: TRUE | G45: TRUE | H45: FALSE | I45: FALSE | J45: FALSE | K45: 36 | L45: =K45-M45 -> 5 | M45: 31
B46: 46048 | C46: Akram | D46: 00-031 | E46: SERVICE CORRIDOR | F46: TRUE | G46: TRUE | H46: FALSE | I46: FALSE | J46: FALSE | K46: 7 | L46: =K46-M46 -> 0 | M46: 7
B47: 46027 | C47: Tarik | D47: 00-032 | E47: Waste holding | F47: TRUE | G47: TRUE | H47: FALSE | I47: FALSE | J47: FALSE | K47: 16 | L47: =K47-M47 -> 0 | M47: 16
B48: 46026 | C48: Arvind | D48: 00-033 | E48: W.C. | F48: TRUE | G48: TRUE | H48: FALSE | I48: FALSE | J48: FALSE | K48: 12 | L48: =K48-M48 -> 0 | M48: 12
B49: 46027 | C49: Tarik | D49: 00-034 | E49: DIRTY LINEN HOLDING | F49: TRUE | G49: TRUE | H49: FALSE | I49: FALSE | J49: FALSE | K49: 6 | L49: =K49-M49 -> 0 | M49: 6
B50: 46027 | C50: Tarik | D50: 00-035 | E50: BUTLER REST AREA | F50: TRUE | G50: TRUE | H50: FALSE | I50: FALSE | J50: FALSE | K50: 13 | L50: =K50-M50 -> 4 | M50: 9
D51: 00-036 | E51: HOTEL CIRCULATION | F51: FALSE | G51: FALSE | H51: FALSE | I51: FALSE | J51: FALSE | L51: =K51-M51 -> 0 | O51: Stage 1a Completion of Operator Inspection (Pre FFE) | R51: Stage 1b Completion of De-Snagging and close out operator Comments/Deep Cleaning
D52: 00-037 | E52: GUEST LIFT LOBBY | F52: FALSE | G52: FALSE | H52: FALSE | I52: FALSE | J52: FALSE | L52: =K52-M52 -> 0
D53: 00-038 | E53: HOTEL CIRCULATION | F53: FALSE | G53: FALSE | H53: FALSE | I53: FALSE | J53: FALSE | L53: =K53-M53 -> 0
D54: 00-039 | E54: GUEST STAIR - 04 | F54: FALSE | G54: FALSE | H54: FALSE | I54: FALSE | J54: FALSE | L54: =K54-M54 -> 0 | O54: TOTAL | P54: =P55+P56 -> 77 | R54: TOTAL | S54: =S55+S56 -> 77
...

Sheet BOH L01
B2: MENU
B5: SNAGGED DATE | C5: SNAGGED BY | D5: ROOM NO. | E5: ROOM NAME | F5: Stage 1a Completion of Operator Inspection (Pre FFE) | G5: Stage 1b Completion of De-Snagging and close out operator Comments/Deep Cleaning | H5: Completion of FF&E installation | I5: Stage 2a Completion of Operator Inspection (Post FFE) | J5: Stage 2b Completion of De-Snagging /Sparkle Cleaning and handover | K5: Total Snag Raised | L5: Total Snag Open | M5: Total Snag Closed | U5: list
D6: Column1 | E6: Column2 | F6: Column3 | G6: Column4 | H6: Column5 | I6: Column6 | J6: Column7 | K6: Column8 | L6: Column9 | M6: Column10
D7: 01-211 | E7: SCREENING EQUIPMENT ROOM | F7: FALSE | G7: FALSE | H7: FALSE | I7: FALSE | J7: FALSE
D8: 01-? | E8: RAMP AREA | F8: FALSE | G8: FALSE | H8: FALSE | I8: FALSE | J8: FALSE | L8: =(BOHL01[[#This Row],[Column8]]-M8) -> 0 | U8: Arvind
D9: 01-000 | E9: FUNICULAR DROP OFF - VILLAGE SQUARE LEVEL | F9: FALSE | G9: FALSE | H9: FALSE | I9: FALSE | J9: FALSE | L9: =(BOHL01[[#This Row],[Column8]]-M9) -> 0 | U9: Thayalaraj
B10: 46042 | C10: Akram | D10: 01-001 | E10: ETS | F10: TRUE | G10: TRUE | H10: FALSE | I10: FALSE | J10: FALSE | K10: 48 | L10: =(BOHL01[[#This Row],[Column8]]-M10) -> 29 | M10: 19 | U10: Abdulrahman
B11: 46069 | C11: Tarik | D11: 01-002 | E11: FERTILIZER BINS | F11: TRUE | G11: TRUE | H11: FALSE | I11: FALSE | J11: FALSE | K11: 11 | L11: =(BOHL01[[#This Row],[Column8]]-M11) -> 5 | M11: 6 | U11: Naseer
B12: 46055 | C12: Nawaf | D12: 01-004 | E12: SUMP PIT & PUMP ROOM | F12: TRUE | G12: FALSE | H12: FALSE | I12: FALSE | J12: FALSE | K12: 8 | L12: =(BOHL01[[#This Row],[Column8]]-M12) -> 8 | M12: 0 | U12: M.Adel
B13: 46069 | C13: Tarik | D13: 01-005 | E13: LANDSCAPE MAINTENANCE | F13: TRUE | G13: FALSE | H13: FALSE | I13: FALSE | J13: FALSE | K13: 6 | L13: =(BOHL01[[#This Row],[Column8]]-M13) -> 6 | M13: 0 | U13: Tarik
B14: 46121 | C14: Tarik | D14: 01-006 | E14: MAINTENANCE YARD | F14: TRUE | G14: FALSE | H14: FALSE | I14: FALSE | J14: FALSE | K14: 28 | L14: =(BOHL01[[#This Row],[Column8]]-M14) -> 28 | M14: 0 | U14: Akram
D15: 01-008 | E15: FUNICULAR DROP OFF - VILLAGE SQUARE LEVEL | F15: FALSE | G15: FALSE | H15: FALSE | I15: FALSE | J15: FALSE | L15: =(BOHL01[[#This Row],[Column8]]-M15) -> 0 | U15: Prasanna
D16: 01-009 | E16: INTERFACE ROOM | F16: FALSE | G16: FALSE | H16: FALSE | I16: FALSE | J16: FALSE | L16: =(BOHL01[[#This Row],[Column8]]-M16) -> 0 | U16: Suresh
B17: 46044 | C17: Thayalaraj | D17: 01-010 | E17: WORKSHOP | F17: TRUE | G17: TRUE | H17: FALSE | I17: FALSE | J17: FALSE | K17: 10 | L17: =(BOHL01[[#This Row],[Column8]]-M17) -> 4 | M17: 6 | U17: Mosab
B18: 46043 | C18: Akram | D18: 01-013 | E18: CHIEF ENGINEER OFFICE | F18: TRUE | G18: TRUE | H18: FALSE | I18: FALSE | J18: FALSE | K18: 20 | L18: =(BOHL01[[#This Row],[Column8]]-M18) -> 5 | M18: 15 | U18: Nawaf
B19: 46043 | C19: Ibrar | D19: 01-014 | E19: ENGINEERING COORDINATOR | F19: TRUE | G19: TRUE | H19: FALSE | I19: FALSE | J19: FALSE | K19: 10 | L19: =(BOHL01[[#This Row],[Column8]]-M19) -> 0 | M19: 10 | U19: Hafil
B20: 46043 | C20: Ibrar | D20: 01-14a | E20: DETERGENT STORE | F20: TRUE | G20: TRUE | H20: FALSE | I20: FALSE | J20: FALSE | K20: 3 | L20: =(BOHL01[[#This Row],[Column8]]-M20) -> 0 | M20: 3 | U20: Ibrar
B21: 46043 | C21: Ibrar | D21: 01-014a | E21: ASSISTANT CHIEF ENGINEER | F21: TRUE | G21: TRUE | H21: FALSE | I21: FALSE | J21: FALSE | K21: 3 | L21: =(BOHL01[[#This Row],[Column8]]-M21) -> 0 | M21: 3 | U21: Brigitta
B22: 46043 | C22: Ibrar | D22: 01-014b | E22: ADMINISTRATIVE ASSISTANT | F22: TRUE | G22: TRUE | H22: FALSE | I22: FALSE | J22: FALSE | K22: 1 | L22: =(BOHL01[[#This Row],[Column8]]-M22) -> 0 | M22: 1 | U22: Ahmed Abdelghany
B23: 46043 | C23: Ibrar | D23: 01-015 | E23: PLAN ROOM & DRAWING BOARD | F23: TRUE | G23: TRUE | H23: FALSE | I23: FALSE | J23: FALSE | K23: 11 | L23: =(BOHL01[[#This Row],[Column8]]-M23) -> 3 | M23: 8 | U23: Simon Gonsalves
B24: 46065 | C24: Akram | D24: 01-016 | E24: MAIN COMMS. ROOM | F24: TRUE | G24: TRUE | H24: FALSE | I24: FALSE | J24: FALSE | K24: 18 | L24: =(BOHL01[[#This Row],[Column8]]-M24) -> 8 | M24: 10 | U24: Engineering team
B25: 46043 | C25: Tarik | D25: 00-017 | E25: UPHOLSTERY SHOP & FABRIC STO. | F25: TRUE | G25: TRUE | H25: FALSE | I25: FALSE | J25: FALSE | K25: 13 | L25: =(BOHL01[[#This Row],[Column8]]-M25) -> 4 | M25: 9
B26: 46043 | C26: Ibrar | D26: 01-018 | E26: TOILET | F26: TRUE | G26: TRUE | H26: FALSE | I26: FALSE | J26: FALSE | K26: 7 | L26: =(BOHL01[[#This Row],[Column8]]-M26) -> 1 | M26: 6
B27: 46043 | C27: Ibrar | D27: 01-019 | E27: SECURE PARTS STO. | F27: TRUE | G27: TRUE | H27: FALSE | I27: FALSE | J27: FALSE | K27: 14 | L27: =(BOHL01[[#This Row],[Column8]]-M27) -> 7 | M27: 7
B28: 46043 | C28: Hafil | D28: 01-020 | E28: PAINT SHOP & STORE | F28: TRUE | G28: TRUE | H28: FALSE | I28: FALSE | J28: FALSE | K28: 14 | L28: =(BOHL01[[#This Row],[Column8]]-M28) -> 4 | M28: 10
B29: 46043 | C29: Thayalaraj | D29: 01-021 | E29: CARPENTRY SHOP | F29: TRUE | G29: TRUE | H29: FALSE | I29: FALSE | J29: FALSE | K29: 12 | L29: =(BOHL01[[#This Row],[Column8]]-M29) -> 2 | M29: 10
D30: 01-022 | E30: RD & E 2 | F30: FALSE | G30: FALSE | H30: FALSE | I30: FALSE | J30: FALSE | L30: =(BOHL01[[#This Row],[Column8]]-M30) -> 0
B31: 46043 | C31: Tarik | D31: 01-023 | E31: RMU ROOM | F31: TRUE | G31: TRUE | H31: FALSE | I31: FALSE | J31: FALSE | K31: 22 | L31: =(BOHL01[[#This Row],[Column8]]-M31) -> 20 | M31: 2
B32: 46124 | C32: Naser | D32: 01-024 | E32: SERVICE CORRIDOR | F32: TRUE | G32: FALSE | H32: FALSE | I32: FALSE | J32: FALSE | K32: 41 | L32: =(BOHL01[[#This Row],[Column8]]-M32) -> 40 | M32: 1
B33: 46043 | C33: Tarik | D33: 01-026 | E33: TRANSFORMER ROOMS | F33: TRUE | G33: FALSE | H33: FALSE | I33: FALSE | J33: FALSE | K33: 13 | L33: =(BOHL01[[#This Row],[Column8]]-M33) -> 12 | M33: 1
B34: 46121 | C34: Naser | D34: 01-027 | E34: SERVICE CORRIDOR | F34: TRUE | G34: FALSE | H34: FALSE | I34: FALSE | J34: FALSE | K34: 55 | L34: =(BOHL01[[#This Row],[Column8]]-M34) -> 55
B35: 46043 | C35: Akram | D35: 01-028 | E35: LV PANEL ROOM | F35: TRUE | G35: TRUE | H35: FALSE | I35: FALSE | J35: FALSE | K35: 34 | L35: =(BOHL01[[#This Row],[Column8]]-M35) -> 26 | M35: 8
D36: 01-028 | E36: GENERATOR ROOM | F36: FALSE | G36: FALSE | H36: FALSE | I36: FALSE | J36: FALSE | L36: =(BOHL01[[#This Row],[Column8]]-M36) -> 0
D37: 01-030 | E37: HOTEL CIRCULATION | F37: FALSE | G37: FALSE | H37: FALSE | I37: FALSE | J37: FALSE | L37: =(BOHL01[[#This Row],[Column8]]-M37) -> 0
D38: 01-030 | E38: HOTEL CIRCULATION | F38: FALSE | G38: FALSE | H38: FALSE | I38: FALSE | J38: FALSE | L38: =(BOHL01[[#This Row],[Column8]]-M38) -> 0
D39: 01-031 | E39: GUEST LIFT LOBBY | F39: FALSE | G39: FALSE | H39: FALSE | I39: FALSE | J39: FALSE | L39: =(BOHL01[[#This Row],[Column8]]-M39) -> 0
D40: 01-032 | E40: HVAC SHAFT | F40: FALSE | G40: FALSE | H40: FALSE | I40: FALSE | J40: FALSE | L40: =(BOHL01[[#This Row],[Column8]]-M40) -> 0
D41: 01-033 | E41: MAIN CIRCULATION | F41: TRUE | G41: TRUE | H41: FALSE | I41: FALSE | J41: FALSE | K41: 66 | L41: =(BOHL01[[#This Row],[Column8]]-M41) -> 25 | M41: 41
B42: 46051 | C42: Naser | D42: 01-034 | E42: GENERAL STORAGE (CHARCOAL STORE) | F42: TRUE | G42: FALSE | H42: FALSE | I42: FALSE | J42: FALSE | K42: 10 | L42: =(BOHL01[[#This Row],[Column8]]-M42) -> 6 | M42: 4
B43: 46049 | C43: Naser | D43: 01-035 | E43: CR ROOM | F43: TRUE | G43: FALSE | H43: FALSE | I43: FALSE | J43: FALSE | K43: 10 | L43: =(BOHL01[[#This Row],[Column8]]-M43) -> 10
...

Sheet BOH L02
B2: MENU
B5: SNAGGED DATE | C5: SNAGGED BY | D5: ROOM NO. | E5: ROOM NAME | F5: Stage 1a Completion of Operator Inspection (Pre FFE) | G5: Stage 1b Completion of De-Snagging and close out operator Comments/Deep Cleaning | H5: Completion of FF&E installation | I5: Stage 2a Completion of Operator Inspection (Post FFE) | J5: Stage 2b Completion of De-Snagging /Sparkle Cleaning and handover | K5: Total Snag Raised | L5: Total Snag Open | M5: Total Snag Closed | Z5: list
D6: Column1 | E6: Column2 | F6: Column3 | G6: Column4 | H6: Column5 | I6: Column6 | J6: Column7 | K6: Column8 | L6: Column9 | M6: Column10 | O6: Stage 1a Completion of Operator Inspection (Pre FFE) | R6: Stage 1b Completion of De-Snagging and close out operator Comments/Deep Cleaning
D7: 02-002 | E7: SERVICE PANTRY | F7: FALSE | G7: FALSE | H7: FALSE | I7: FALSE | J7: FALSE
D8: 02-004 | E8: Waste Holding | F8: FALSE | G8: FALSE | H8: FALSE | I8: FALSE | J8: FALSE
D9: 02-006 | E9: BUTLER REST AREA | F9: FALSE | G9: FALSE | H9: FALSE | I9: FALSE | J9: FALSE | O9: TOTAL | P9: =P10+P11 -> 39 | R9: TOTAL | S9: =S10+S11 -> 39
D10: 02-008 | E10: CLEAN LINEN & HOUSEKEEPING STORAGE | F10: FALSE | G10: FALSE | H10: FALSE | I10: FALSE | J10: FALSE | O10: completed | P10: =COUNTIFS(F7:F45,TRUE) -> 0 | R10: completed | S10: =COUNTIFS(G7:G45,TRUE) -> 0
D11: 02-010 | E11: MAIN CIRCULATION | F11: FALSE | G11: FALSE | H11: FALSE | I11: FALSE | J11: FALSE | O11: pending | P11: =COUNTIFS(F7:F45,FALSE) -> 39 | R11: pending | S11: =COUNTIFS(G7:G45,FALSE) -> 39
D12: 02-012 | E12: ELECTRICAL ROOM | F12: FALSE | G12: FALSE | H12: FALSE | I12: FALSE | J12: FALSE
D13: 02-014 | E13: MAIN CIRCULATION | F13: FALSE | G13: FALSE | H13: FALSE | I13: FALSE | J13: FALSE
D14: 02-016 | E14: HVAC SHAFT | F14: FALSE | G14: FALSE | H14: FALSE | I14: FALSE | J14: FALSE
D15: 02-020 | E15: MAIN CIRCULATION | F15: FALSE | G15: FALSE | H15: FALSE | I15: FALSE | J15: FALSE
D16: 02-022 | E16: SERVICE CORRIDOR | F16: FALSE | G16: FALSE | H16: FALSE | I16: FALSE | J16: FALSE
D17: 02-024 | E17: SERVICE CORRIDOR | F17: FALSE | G17: FALSE | H17: FALSE | I17: FALSE | J17: FALSE
D18: 02-028 | E18: CR ROOM | F18: FALSE | G18: FALSE | H18: FALSE | I18: FALSE | J18: FALSE
D19: 02-030 | E19: CART PARKING AREA | F19: FALSE | G19: FALSE | H19: FALSE | I19: FALSE | J19: FALSE
D20: 02-033 | E20: HOUSEKEEPING & SERVICE PANTRY | F20: FALSE | G20: FALSE | H20: FALSE | I20: FALSE | J20: FALSE
D21: 02-036 | E21: GUEST LIFT LOBBY | F21: FALSE | G21: FALSE | H21: FALSE | I21: FALSE | J21: FALSE
D22: 02-038 | E22: CART PARKING AREA | F22: FALSE | G22: FALSE | H22: FALSE | I22: FALSE | J22: FALSE
D23: 02-040 | E23: CR ROOM | F23: FALSE | G23: FALSE | H23: FALSE | I23: FALSE | J23: FALSE
... D45: 02-085 | E45: CHERRY PICKER PARKING | F45: FALSE | G45: FALSE | H45: FALSE | I45: FALSE | J45: FALSE
K46: =SUM(Table25[Column8]) -> 0 | L46: =SUM(Table25[Column9]) -> 0 | M46: =SUM(Table25[Column10]) -> 0

Sheet BOH L03
B2: MENU
B5: SNAGGED DATE | C5: SNAGGED BY | D5: ROOM NO. | E5: ROOM NAME | F5: Stage 1a Completion of Operator Inspection (Pre FFE) | G5: Stage 1b Completion of De-Snagging and close out operator Comments/Deep Cleaning | H5: Completion of FF&E installation | I5: Stage 2a Completion of Operator Inspection (Post FFE) | J5: Stage 2b Completion of De-Snagging /Sparkle Cleaning and handover | K5: Total Snag Raised | L5: Total Snag Open | M5: Total Snag Closed | Z5: list
D6: Column1 | E6: Column2 | F6: Column3 | G6: Column4 | H6: Column5 | I6: Column6 | J6: Column7 | K6: Column8 | L6: Column9 | M6: Column10
D7: 03-003 | E7: GOURMET BISTRO DINING | F7: FALSE | G7: FALSE | H7: FALSE | I7: FALSE | J7: FALSE
D8: 03-005 | E8: MAIN CIRCULATION | F8: FALSE | G8: FALSE | H8: FALSE | I8: FALSE | J8: FALSE | O8: Stage 1a Completion of Operator Inspection (Pre FFE) | R8: Stage 1b Completion of De-Snagging and close out operator Comments/Deep Cleaning
D9: 03-007 | E9: CR ROOM | F9: FALSE | G9: FALSE | H9: FALSE | I9: FALSE | J9: FALSE
D10: 03-009 | E10: PANTRY VENTILATION | F10: FALSE | G10: FALSE | H10: FALSE | I10: FALSE | J10: FALSE
D11: 03-011 | E11: SERVICE LIFT LOBBY | F11: FALSE | G11: FALSE | H11: FALSE | I11: FALSE | J11: FALSE | O11: TOTAL | P11: =P12+P13 -> 38 | R11: TOTAL | S11: =S12+S13 -> 38
D12: 03-013 | E12: MEP SERVICE CORRIDOR | F12: FALSE | G12: FALSE | H12: FALSE | I12: FALSE | J12: FALSE | O12: completed | P12: =COUNTIFS(F7:F44,TRUE) -> 0 | R12: completed | S12: =COUNTIFS(G7:G44,TRUE) -> 0
D13: 03-016 | E13: GOURMET BESTRO AHU ROOM | F13: FALSE | G13: FALSE | H13: FALSE | I13: FALSE | J13: FALSE | O13: pending | P13: =COUNTIFS(F7:F44,FALSE) -> 38 | R13: pending | S13: =COUNTIFS(G7:G44,FALSE) -> 38
D14: 03-018 | E14: HVAC SHAFT | F14: FALSE | G14: FALSE | H14: FALSE | I14: FALSE | J14: FALSE
D15: 03-020 | E15: GUEST LIFT LOBBY | F15: FALSE | G15: FALSE | H15: FALSE | I15: FALSE | J15: FALSE
D16: 03-023 | E16: DIRTY LINEN HOLDING | F16: FALSE | G16: FALSE | H16: FALSE | I16: FALSE | J16: FALSE
D17: 03-026 | E17: ELECTRICAL ROOM | F17: FALSE | G17: FALSE | H17: FALSE | I17: FALSE | J17: FALSE
D18: 03-028 | E18: SERVICE LIFT LOBBY | F18: FALSE | G18: FALSE | H18: FALSE | I18: FALSE | J18: FALSE
D19: 03-030 | E19: HVAC SHAFT | F19: FALSE | G19: FALSE | H19: FALSE | I19: FALSE | J19: FALSE
D20: 03-032 | E20: ELECTRICAL ROOM | F20: FALSE | G20: FALSE | H20: FALSE | I20: FALSE | J20: FALSE
D21: 03-034 | E21: MEP SERVICE CORRIDOR | F21: FALSE | G21: FALSE | H21: FALSE | I21: FALSE | J21: FALSE
D22: 03-037 | E22: CART PARKING AREA | F22: FALSE | G22: FALSE | H22: FALSE | I22: FALSE | J22: FALSE
D23: 03-038 | E23: SERVICE LIFT LOBBY | F23: FALSE | G23: FALSE | H23: FALSE | I23: FALSE | J23: FALSE
D24: 03-040 | E24: GUEST LIFT LOBBY | F24: FALSE | G24: FALSE | H24: FALSE | I24: FALSE | J24: FALSE
D25: 03-042 | E25: DIRTY LINEN HOLDING | F25: FALSE | G25: FALSE | H25: FALSE | I25: FALSE | J25: FALSE
... D44: 03-081 | E44: ELV SHAFT | F44: FALSE | G44: FALSE | H44: FALSE | I44: FALSE | J44: FALSE
K45: =SUM(K7:K44) -> 0 | L45: =SUM(L7:L44) -> 0 | M45: =SUM(M7:M44) -> 0

Sheet BOH L04
B2: MENU
B5: SNAGGED DATE | C5: SNAGGED BY | D5: ROOM NO. | E5: ROOM NAME | F5: Stage 1a Completion of Operator Inspection (Pre FFE) | G5: Stage 1b Completion of De-Snagging and close out operator Comments/Deep Cleaning | H5: Completion of FF&E installation | I5: Stage 2a Completion of Operator Inspection (Post FFE) | J5: Stage 2b Completion of De-Snagging /Sparkle Cleaning and handover | K5: Total Snag Raised | L5: Total Snag Open | M5: Total Snag Closed | Z5: list
D6: Column1 | E6: Column2 | F6: Column3 | G6: Column4 | H6: Column5 | I6: Column6 | J6: Column7 | K6: Column8 | L6: Column9 | M6: Column10
D7: 04-000E | E7: DISABLED TOILET | F7: FALSE | G7: FALSE | H7: FALSE | I7: FALSE | J7: FALSE
D8: 04-001 | E8: SUNSET BAR PANTRY | F8: FALSE | G8: FALSE | H8: FALSE | I8: FALSE | J8: FALSE
D9: 04-003 | E9: AHU ROOM | F9: FALSE | G9: FALSE | H9: FALSE | I9: FALSE | J9: FALSE
D10: 04-005 | E10: TRAINING COORDINATOR | F10: FALSE | G10: FALSE | H10: FALSE | I10: FALSE | J10: FALSE
D11: 04-007 | E11: CIRCULATION | F11: FALSE | G11: FALSE | H11: FALSE | I11: FALSE | J11: FALSE
D12: 04-009 | E12: HR COORDINATOR | F12: FALSE | G12: FALSE | H12: FALSE | I12: FALSE | J12: FALSE
D13: 04-011 | E13: F&B MANAGER | F13: FALSE | G13: FALSE | H13: FALSE | I13: FALSE | J13: FALSE | O13: Stage 1a Completion of Operator Inspection (Pre FFE) | R13: Stage 1b Completion of De-Snagging and close out operator Comments/Deep Cleaning
D14: 04-013 | E14: F&B RESERVATIONS | F14: FALSE | G14: FALSE | H14: FALSE | I14: FALSE | J14: FALSE
D15: 04-015 | E15: F&B ADMIN. ASSISTANT | F15: FALSE | G15: FALSE | H15: FALSE | I15: FALSE | J15: FALSE
D16: 04-017 | E16: F&B ASSIST. DIR. OF CATERING / EVENT | F16: FALSE | G16: FALSE | H16: FALSE | I16: FALSE | J16: FALSE | O16: TOTAL | P16: =P17+P18 -> 48 | R16: TOTAL | S16: =S17+S18 -> 48
D17: 04-019 | E17: F&B DIRECTOR OF REVENUE MNG. | F17: FALSE | G17: FALSE | H17: FALSE | I17: FALSE | J17: FALSE | O17: completed | P17: =COUNTIFS(F7:F54,TRUE) -> 0 | R17: completed | S17: =COUNTIFS(G7:G54,TRUE) -> 0
D18: 04-020a | E18: FINANCE - FILING | F18: FALSE | G18: FALSE | H18: FALSE | I18: FALSE | J18: FALSE | O18: pending | P18: =COUNTIFS(F7:F54,FALSE) -> 48 | R18: pending | S18: =COUNTIFS(G7:G54,FALSE) -> 48
D19: 04-022 | E19: FEMALE TOILET | F19: FALSE | G19: FALSE | H19: FALSE | I19: FALSE | J19: FALSE
D20: 04-024 | E20: CIRCULATION | F20: FALSE | G20: FALSE | H20: FALSE | I20: FALSE | J20: FALSE
D21: 04-026 | E21: PANTRY | F21: FALSE | G21: FALSE | H21: FALSE | I21: FALSE | J21: FALSE
D22: 04-028 | E22: CR ROOM | F22: FALSE | G22: FALSE | H22: FALSE | I22: FALSE | J22: FALSE
D23: 04-030 | E23: SERVICE LIFT LOBBY | F23: FALSE | G23: FALSE | H23: FALSE | I23: FALSE | J23: FALSE
D24: 04-033 | E24: HVAC SHAFT | F24: FALSE | G24: FALSE | H24: FALSE | I24: FALSE | J24: FALSE
D25: 04-034 | E25: HVAC SHAFT | F25: FALSE | G25: FALSE | H25: FALSE | I25: FALSE | J25: FALSE
D26: 04-035b | E26: CART PARKING AREA | F26: FALSE | G26: FALSE | H26: FALSE | I26: FALSE | J26: FALSE
D27: 04-037 | E27: MAIN FHAU | F27: FALSE | G27: FALSE | H27: FALSE | I27: FALSE | J27: FALSE
D28: 04-039 | E28: BUTLER'S REST AREA | F28: FALSE | G28: FALSE | H28: FALSE | I28: FALSE | J28: FALSE
D29: 04-041 | E29: DIRTY LINEN HOLDING | F29: FALSE | G29: FALSE | H29: FALSE | I29: FALSE | J29: FALSE
D30: 04-043 | E30: DIRTY LINEN HOLDING | F30: FALSE | G30: FALSE | H30: FALSE | I30: FALSE | J30: FALSE
... D54: 04-103 | E54: CHERRY PICKER PARKING | F54: FALSE | G54: FALSE | H54: FALSE | I54: FALSE | J54: FALSE
K55: =SUM(Table27[Column8]) -> 0 | L55: =SUM(Table27[Column9]) -> 0 | M55: =SUM(Table27[Column10]) -> 0

Sheet Guest Room 
B2: MENU
B4: CLUTERS | C4: Area | D4: No of Keys | E4: Stage 1a Completion of Operator Inspection (Pre FFE) | F4: Stage 1b Completion of De-Snagging and close out operator Comments/Deep Cleaning | G4: Completion of FF&E installation | H4: Stage 2a Completion of Operator Inspection (Post FFE) | I4: Stage 2b Completion of De-Snagging /Sparkle Cleaning and handover | J4: Total Snag Raised | K4: Total Snag Open | L4: Total Snag Closed | O4: Stage 1a Completion of Operator Inspection (Pre FFE) | Q4: Stage 1b Completion of De-Snagging and close out operator Comments/Deep Cleaning
C5: Column1 | D5: Column2 | E5: Column3 | F5: Column4 | G5: Column5 | H5: Column6 | I5: Column7 | J5: Column8 | K5: Column9 | L5: Column10
B6: CLUSTER "A" | C6: A0 | D6: 4 | E6: TRUE | F6: TRUE | G6: FALSE | H6: FALSE | I6: FALSE | J6: 400 | K6: =J6-L6 -> 139 | L6: 261 | O6: TOTAL | P6: =P7+P8 -> 84 | Q6: TOTAL | R6: =R7+R8 -> 84
C7: A1 | D7: 4 | E7: TRUE | F7: TRUE | G7: FALSE | H7: FALSE | I7: FALSE | J7: 436 | K7: =J7-L7 -> 99 | L7: 337 | O7: completed | P7: =COUNTIFS(E6:E89,TRUE) -> 34 | Q7: completed | R7: =COUNTIFS(F6:F89,TRUE) -> 29
C8: A2 | D8: 6 | E8: FALSE | F8: FALSE | G8: FALSE | H8: FALSE | I8: FALSE | K8: =J8-L8 -> 0 | O8: pending | P8: =COUNTIFS(E6:E89,FALSE) -> 50 | Q8: pending | R8: =COUNTIFS(F6:F89,FALSE) -> 55
C9: A3 | D9: 4 | E9: FALSE | F9: FALSE | G9: FALSE | H9: FALSE | I9: FALSE | K9: =J9-L9 -> 0
C10: A4 | D10: 4 | E10: FALSE | F10: FALSE | G10: FALSE | H10: FALSE | I10: FALSE | K10: =J10-L10 -> 0
B11: CLUSTER "B" | C11: B0 | D11: 8 | E11: TRUE | F11: TRUE | G11: FALSE | H11: FALSE | I11: FALSE | J11: 840 | K11: =J11-L11 -> 318 | L11: 522
C12: B1 | D12: 8 | E12: TRUE | F12: TRUE | G12: FALSE | H12: FALSE | I12: FALSE | J12: 805 | K12: =J12-L12 -> 348 | L12: 457
C13: B2 | D13: 5 | E13: FALSE | F13: FALSE | G13: FALSE | H13: FALSE | I13: FALSE | K13: =J13-L13 -> 0
C14: B3 | D14: 5 | E14: FALSE | F14: FALSE | G14: FALSE | H14: FALSE | I14: FALSE | K14: =J14-L14 -> 0
C15: B4 | D15: 4 | E15: FALSE | F15: FALSE | G15: FALSE | H15: FALSE | I15: FALSE | K15: =J15-L15 -> 0
B16: CLUSTER "C" | C16: C0 | D16: 6 | E16: TRUE | F16: TRUE | G16: FALSE | H16: FALSE | I16: FALSE | J16: 484 | K16: =J16-L16 -> 278 | L16: 206
C17: C1 | D17: 6 | E17: TRUE | F17: TRUE | G17: FALSE | H17: FALSE | I17: FALSE | J17: 573 | K17: =J17-L17 -> 335 | L17: 238
C18: C2 | D18: 4 | E18: FALSE | F18: FALSE | G18: FALSE | H18: FALSE | I18: FALSE | K18: =J18-L18 -> 0
C19: C3 | D19: 4 | E19: FALSE | F19: FALSE | G19: FALSE | H19: FALSE | I19: FALSE | K19: =J19-L19 -> 0
C20: C4 | D20: 8 | E20: FALSE | F20: FALSE | G20: FALSE | H20: FALSE | I20: FALSE | K20: =J20-L20 -> 0
B21: CLUSTER "D" | C21: D0 | D21: 7 | E21: TRUE | F21: TRUE | G21: FALSE | H21: FALSE | I21: FALSE | J21: 549 | K21: =J21-L21 -> 329 | L21: 220
C22: D1 | D22: 7 | E22: TRUE | F22: TRUE | G22: FALSE | H22: FALSE | I22: FALSE | J22: 271 | K22: =J22-L22 -> 160 | L22: 111
C23: D2 | D23: 4 | E23: FALSE | F23: FALSE | G23: FALSE | H23: FALSE | I23: FALSE | K23: =J23-L23 -> 0
C24: D3 | D24: 4 | E24: FALSE | F24: FALSE | G24: FALSE | H24: FALSE | I24: FALSE | K24: =J24-L24 -> 0
C25: D4 | D25: 6 | E25: FALSE | F25: FALSE | G25: FALSE | H25: FALSE | I25: FALSE | K25: =J25-L25 -> 0
B26: CLUSTER "E" | C26: E0 | D26: 8 | E26: TRUE | F26: TRUE | G26: FALSE | H26: FALSE | I26: FALSE | J26: 1070 | K26: =J26-L26 -> 397 | L26: 673
C27: E1 | D27: 8 | E27: TRUE | F27: TRUE | G27: FALSE | H27: FALSE | I27: FALSE | J27: 928 | K27: =J27-L27 -> 224 | L27: 704
C28: E2 | D28: 6 | E28: FALSE | F28: FALSE | G28: FALSE | H28: FALSE | I28: FALSE | K28: =J28-L28 -> 0
C29: E3 | D29: 6 | E29: FALSE | F29: FALSE | G29: FALSE | H29: FALSE | I29: FALSE | K29: =J29-L29 -> 0
C30: E4 | D30: 5 | E30: FALSE | F30: FALSE | G30: FALSE | H30: FALSE | I30: FALSE | K30: =J30-L30 -> 0
B31: CLUSTER "F" | C31: F0 | D31: 5 | E31: TRUE | F31: TRUE | G31: FALSE | H31: FALSE | I31: FALSE | J31: 342 | K31: =J31-L31 -> 204 | L31: 138
C32: F1 | D32: 5 | E32: TRUE | F32: TRUE | G32: FALSE | H32: FALSE | I32: FALSE | J32: 300 | K32: =J32-L32 -> 198 | L32: 102
C33: F2 | D33: 9 | E33: FALSE | F33: FALSE | G33: FALSE | H33: FALSE | I33: FALSE | K33: =J33-L33 -> 0
C34: F3 | D34: 6 | E34: FALSE | F34: FALSE | G34: FALSE | H34: FALSE | I34: FALSE | K34: =J34-L34 -> 0
C35: F4 | D35: 5 | E35: FALSE | F35: FALSE | G35: FALSE | H35: FALSE | I35: FALSE | K35: =J35-L35 -> 0
B36: CLUSTER "G" | C36: G1 | D36: 4 | E36: TRUE | F36: TRUE | G36: FALSE | H36: FALSE | I36: FALSE | J36: 283 | K36: =J36-L36 -> 190 | L36: 93
C37: G2 | D37: 4 | E37: FALSE | F37: FALSE | G37: FALSE | H37: FALSE | I37: FALSE | K37: =J37-L37 -> 0
C38: G3 | D38: 8 | E38: FALSE | F38: FALSE | G38: FALSE | H38: FALSE | I38: FALSE | K38: =J38-L38 -> 0
C39: G4 | D39: 4 | E39: FALSE | F39: FALSE | G39: FALSE | H39: FALSE | I39: FALSE | K39: =J39-L39 -> 0
B40: CLUSTER "H" | C40: H0 | D40: 6 | E40: TRUE | F40: TRUE | G40: FALSE | H40: FALSE | I40: FALSE | J40: 601 | K40: =J40-L40 -> 226 | L40: 375
C41: H1 | D41: 6 | E41: TRUE | F41: TRUE | G41: FALSE | H41: FALSE | I41: FALSE | J41: 596 | K41: =J41-L41 -> 304 | L41: 292
C42: H2 | D42: 7 | E42: FALSE | F42: FALSE | G42: FALSE | H42: FALSE | I42: FALSE | K42: =J42-L42 -> 0
...

Sheet ROOM NO & CLUSTERS
B2: MENU
C4: CLUSTER | D4: ROOM NO | E4: CHECK BOX | F4: SNAGGED DATE | G4: SNAGGED BY | I4: Stage 1a Completion of Operator Inspection (Pre FFE)
B5: RING | E5: FALSE | I5: TOTAL | J5: =J6+J7 -> 430
C6: A0 | D6: 92 | E6: TRUE | F6: 46078 | G6: Hafil | I6: completed | J6: =COUNTIFS(E6:E435,TRUE) -> 171
D7: 93 | E7: TRUE | F7: 46078 | G7: Thayalaraj | I7: pending | J7: =COUNTIFS(E6:E435,FALSE) -> 259 | T7: Arvind
D8: 94 | E8: TRUE | F8: 46078 | G8: Nawaf | T8: Thayalaraj
D9: 95 | E9: TRUE | F9: 46078 | G9: Tarik | T9: Abdulrahman
C10: A1 | D10: 192 | E10: TRUE | F10: 46078 | G10: Ibrar | T10: Naseer
D11: 193 | E11: TRUE | F11: 46078 | G11: Nasser | T11: M.Adel
D12: 194 | E12: TRUE | F12: 46078 | G12: Abdulrahman | T12: Tarik
D13: 195 | E13: TRUE | F13: 46078 | G13: Abdulrahman | T13: Akram
C14: A2 | D14: 270 | E14: FALSE | T14: Prasanna
D15: 271 | E15: FALSE | T15: Suresh
D16: 272 | E16: FALSE | T16: Mosab
D17: 273 | E17: FALSE | T17: Nawaf
D18: 274 | E18: FALSE | T18: Hafil
D19: 275 | E19: FALSE | T19: Ibrar
C20: A3 | D20: 360 | E20: FALSE | T20: Brigitta
D21: 361 | E21: FALSE | T21: Ahmed Abdelghany
D22: 362 | E22: FALSE | T22: Simon Gonsalves
D23: 363 | E23: FALSE | T23: Engineering team
C24: A4 | D24: 433 | E24: FALSE
D25: 434 | E25: FALSE
D26: 435 | E26: FALSE
D27: 436 | E27: FALSE
C28: B0 | D28: 84 | E28: TRUE | F28: 46113 | G28: Nasser
D29: 85 | E29: TRUE | F29: 46113 | G29: Tarik
D30: 86 | E30: TRUE | F30: 46113 | G30: Thayalaraj
D31: 87 | E31: TRUE | F31: 46113 | G31: Thayalaraj
D32: 88 | E32: TRUE | F32: 46113 | G32: Hafil
D33: 89 | E33: TRUE | F33: 46113 | G33: Hafil
D34: 90 | E34: TRUE | F34: 46113 | G34: Abdulrahman
D35: 91 | E35: TRUE | F35: 46114 | G35: Mosab
C36: B1 | D36: 184 | E36: TRUE | F36: 46113 | G36: Prasanna
D37: 185 | E37: TRUE | F37: 46113 | G37: Prasanna
D38: 186 | E38: TRUE | F38: 46113 | G38: Akram
D39: 187 | E39: TRUE | F39: 46113 | G39: Akram
D40: 188 | E40: TRUE | F40: 46113 | G40: Tarik
D41: 189 | E41: TRUE | F41: 46113 | G41: Tarik
D42: 190 | E42: TRUE | F42: 46113 | G42: Surish
...

Sheet CAFE MAUDE
B2: MENU
C7: SNAGGED DATE | D7: SNAGGED BY | E7: AREA Aconex name | F7: ROOM NO | G7: ROOM NAME | H7: Stage 1a Completion of Operator Inspection (Pre FFE) | I7: Stage 1b Completion of De-Snagging and close out operator Comments/Deep Cleaning | J7: Completion of FF&E installation | K7: Stage 2a Completion of Operator Inspection (Post FFE) | L7: Stage 2b Completion of De-Snagging /Sparkle Cleaning and handover | M7: Total Snag Raised | N7: Total Snag Open | O7: Total Snag Closed | S7: Arvind
E8: GOURMET BISTRO CAFÉ | F8: 03-001 | G8: GOURMET BISTRO TERRACE DINING SEATS | H8: FALSE | I8: FALSE | J8: FALSE | K8: FALSE | L8: FALSE
E9: GOURMET BISTRO CAFÉ | F9: 03-003 | G9: GOURMET BISTRO DINING | H9: FALSE | I9: FALSE | J9: FALSE | K9: FALSE | L9: FALSE
E10: GOURMET BISTRO CAFÉ | F10: 03-005 | G10: COUNTER | H10: FALSE | I10: FALSE | J10: FALSE | K10: FALSE | L10: FALSE
E11: GOURMET BISTRO CAFÉ | F11: 03-007 | G11: FOOD PICK UP | H11: FALSE | I11: FALSE | J11: FALSE | K11: FALSE | L11: FALSE
E12: GOURMET BISTRO CAFÉ | F12: 03-009 | G12: HOT FOOD PRODUCTION | H12: FALSE | I12: FALSE | J12: FALSE | K12: FALSE | L12: FALSE
E13: GOURMET BISTRO CAFÉ | F13: 03-012 | G13: DRY STORAGE | H13: FALSE | I13: FALSE | J13: FALSE | K13: FALSE | L13: FALSE
E14: GOURMET BISTRO CAFÉ | F14: 03-014 | G14: DISH WASHING | H14: FALSE | I14: FALSE | J14: FALSE | K14: FALSE | L14: FALSE
E15: GOURMET BISTRO CAFÉ | F15: 03-017 | G15: LOBBY | H15: FALSE | I15: FALSE | J15: FALSE | K15: FALSE | L15: FALSE
E16: GOURMET BISTRO CAFÉ | F16: 03-023 | G16: TOILET | H16: FALSE | I16: FALSE | J16: FALSE | K16: FALSE | L16: FALSE
E17: GOURMET BISTRO CAFÉ | F17: 03-025 | G17: H.C. TOILET | H17: FALSE | I17: FALSE | J17: FALSE | K17: FALSE | L17: FALSE
E18: GOURMET BISTRO CAFÉ | F18: 03-027 | G18: COUNTER | H18: FALSE | I18: FALSE | J18: FALSE | K18: FALSE | L18: FALSE
M19: =SUM(M8:M18) -> 0 | N19: =SUM(N8:N18) -> 0 | O19: =SUM(O8:O18) -> 0

Sheet 5th Floor
B2: MENU
B5: SNAGGED DATE | C5: SNAGGED BY | D5: AREA | E5: ROOM NO | F5: ROOM NAME | G5: Stage 1a Completion of Operator Inspection (Pre FFE) | H5: Stage 1b Completion of De-Snagging and close out operator Comments/Deep Cleaning | I5: Completion of FF&E installation | J5: Stage 2a Completion of Operator Inspection (Post FFE) | K5: Stage 2b Completion of De-Snagging /Sparkle Cleaning and handover | L5: Total Snag Raised | M5: Total Snag Open | N5: Total Snag Closed
D6: Level 05 - ALL DAY DINING, SPECIALITY RESTAURANT-2, CLUB LOUNGE, SUNSET BAR | E6: 05-001 | F6: GUEST LOBBY | G6: FALSE | H6: FALSE | I6: FALSE | J6: FALSE | K6: FALSE
D7: Level 05 - ALL DAY DINING, SPECIALITY RESTAURANT-2, CLUB LOUNGE, SUNSET BAR | E7: 05-003 | F7: F&B-1(EL TAKOY) | G7: FALSE | H7: FALSE | I7: FALSE | J7: FALSE | K7: FALSE | S7: Arvind
D8: Level 05 - ALL DAY DINING, SPECIALITY RESTAURANT-2, CLUB LOUNGE, SUNSET BAR | E8: 05-005 | F8: F&B-1 PANTRY | G8: FALSE | H8: FALSE | I8: FALSE | J8: FALSE | K8: FALSE | S8: Thayalaraj
D9: Level 05 - ALL DAY DINING, SPECIALITY RESTAURANT-2, CLUB LOUNGE, SUNSET BAR | E9: 05-006 | F9: DISH & GLASS COLLATE | G9: FALSE | H9: FALSE | I9: FALSE | J9: FALSE | K9: FALSE | S9: Abdulrahman
D10: Level 05 - ALL DAY DINING, SPECIALITY RESTAURANT-2, CLUB LOUNGE, SUNSET BAR | E10: 05-008 | F10: TOILET-MALE | G10: FALSE | H10: FALSE | I10: FALSE | J10: FALSE | K10: FALSE | S10: Naseer
D11: Level 05 - ALL DAY DINING, SPECIALITY RESTAURANT-2, CLUB LOUNGE, SUNSET BAR | E11: 05-010 | F11: DISABLE TOILET | G11: FALSE | H11: FALSE | I11: FALSE | J11: FALSE | K11: FALSE | S11: M.Adel
D12: Level 05 - ALL DAY DINING, SPECIALITY RESTAURANT-2, CLUB LOUNGE, SUNSET BAR | E12: 05-011a | F12: ELEC. CL. | G12: FALSE | H12: FALSE | I12: FALSE | J12: FALSE | K12: FALSE | S12: Tarik
D13: Level 05 - ALL DAY DINING, SPECIALITY RESTAURANT-2, CLUB LOUNGE, SUNSET BAR | E13: 05-013 | F13: CIRCULATION - SR2 | G13: FALSE | H13: FALSE | I13: FALSE | J13: FALSE | K13: FALSE | S13: Akram
D14: Level 05 - ALL DAY DINING, SPECIALITY RESTAURANT-2, CLUB LOUNGE, SUNSET BAR | E14: 05-015 | F14: SERVICE STATIONS EXTERNAL 01 | G14: FALSE | H14: FALSE | I14: FALSE | J14: FALSE | K14: FALSE | S14: Prasanna
D15: Level 05 - ALL DAY DINING, SPECIALITY RESTAURANT-2, CLUB LOUNGE, SUNSET BAR | E15: 05-017 | F15: SPECIALITY RESTAURANT-2 TERRACE DINING SEATS(AKIRA BACK BBQ) | G15: FALSE | H15: FALSE | I15: FALSE | J15: FALSE | K15: FALSE | S15: Suresh
D16: Level 05 - ALL DAY DINING, SPECIALITY RESTAURANT-2, CLUB LOUNGE, SUNSET BAR | E16: 05-019 | F16: CIRCULATION - SR2 | G16: FALSE | H16: FALSE | I16: FALSE | J16: FALSE | K16: FALSE | S16: Mosab
D17: Level 05 - ALL DAY DINING, SPECIALITY RESTAURANT-2, CLUB LOUNGE, SUNSET BAR | E17: 05-022 | F17: TOILET-MALE | G17: FALSE | H17: FALSE | I17: FALSE | J17: FALSE | K17: FALSE | S17: Nawaf
D18: Level 05 - ALL DAY DINING, SPECIALITY RESTAURANT-2, CLUB LOUNGE, SUNSET BAR | E18: 05-024 | F18: JANITOR | G18: FALSE | H18: FALSE | I18: FALSE | J18: FALSE | K18: FALSE | S18: Hafil
... D22: Level 05 - ALL DAY DINING, SPECIALITY RESTAURANT-2, CLUB LOUNGE, SUNSET BAR | E22: 05-030 | F22: COLD AND DESSERTS KITCHEN | G22: FALSE | H22: FALSE | I22: FALSE | J22: FALSE | K22: FALSE | S22: Simon Gonsalves
D23: Level 05 - ALL DAY DINING, SPECIALITY RESTAURANT-2, CLUB LOUNGE, SUNSET BAR | E23: 05-032 | F23: CIRCULATION | G23: FALSE | H23: FALSE | I23: FALSE | J23: FALSE | K23: FALSE
D24: Level 05 - ALL DAY DINING, SPECIALITY RESTAURANT-2, CLUB LOUNGE, SUNSET BAR | E24: 05-035 | F24: DRY GOODS STORE | G24: FALSE | H24: FALSE | I24: FALSE | J24: FALSE | K24: FALSE
D25: Level 05 - ALL DAY DINING, SPECIALITY RESTAURANT-2, CLUB LOUNGE, SUNSET BAR | E25: 05-037 | F25: MAIN CIRCULATION | G25: FALSE | H25: FALSE | I25: FALSE | J25: FALSE | K25: FALSE
D26: Level 05 - ALL DAY DINING, SPECIALITY RESTAURANT-2, CLUB LOUNGE, SUNSET BAR | E26: 05-038 | F26: CLEANER'S STORE (DETERGENT) | G26: FALSE | H26: FALSE | I26: FALSE | J26: FALSE | K26: FALSE
D27: Level 05 - ALL DAY DINING, SPECIALITY RESTAURANT-2, CLUB LOUNGE, SUNSET BAR | E27: 05-040 | F27: BEVERAGE STORE | G27: FALSE | H27: FALSE | I27: FALSE | J27: FALSE | K27: FALSE
D28: Level 05 - ALL DAY DINING, SPECIALITY RESTAURANT-2, CLUB LOUNGE, SUNSET BAR | E28: 05-042 | F28: ELECTRICAL CABINET | G28: FALSE | H28: FALSE | I28: FALSE | J28: FALSE | K28: FALSE
D29: Level 05 - ALL DAY DINING, SPECIALITY RESTAURANT-2, CLUB LOUNGE, SUNSET BAR | E29: 05-043 | F29: CHARCOAL STORE | G29: FALSE | H29: FALSE | I29: FALSE | J29: FALSE | K29: FALSE
D30: Level 05 - ALL DAY DINING, SPECIALITY RESTAURANT-2, CLUB LOUNGE, SUNSET BAR | E30: 05-044c | F30: ELEC. CL. | G30: FALSE | H30: FALSE | I30: FALSE | J30: FALSE | K30: FALSE
D31: Level 05 - ALL DAY DINING, SPECIALITY RESTAURANT-2, CLUB LOUNGE, SUNSET BAR | E31: 05-046 | F31: BEVERAGE COLD ROOM | G31: FALSE | H31: FALSE | I31: FALSE | J31: FALSE | K31: FALSE
D32: Level 05 - ALL DAY DINING, SPECIALITY RESTAURANT-2, CLUB LOUNGE, SUNSET BAR | E32: 05-048 | F32: MEAT & POULTRY COLD ROOM | G32: FALSE | H32: FALSE | I32: FALSE | J32: FALSE | K32: FALSE
D33: Level 05 - ALL DAY DINING, SPECIALITY RESTAURANT-2, CLUB LOUNGE, SUNSET BAR | E33: 05-050 | F33: COLD ROOM | G33: FALSE | H33: FALSE | I33: FALSE | J33: FALSE | K33: FALSE
D34: Level 05 - ALL DAY DINING, SPECIALITY RESTAURANT-2, CLUB LOUNGE, SUNSET BAR | E34: 05-052 | F34: CIRCULATION | G34: FALSE | H34: FALSE | I34: FALSE | J34: FALSE | K34: FALSE
... D70: Level 06 - ALL DAY DINING, SPECIALITY RESTAURANT-2, CLUB LOUNGE, SUNSET BAR | E70: 06-037 | F70: CIRCULATION | G70: FALSE | H70: FALSE | I70: FALSE | J70: FALSE | K70: FALSE
L71: =SUM(L6:L70) -> 0 | M71: =SUM(M6:M70) -> 0 | N71: =SUM(N6:N70) -> 0

Sheet 6th Floor
B2: MENU
B5: SNAGGED DATE | C5: SNAGGED BY | D5: AREA | E5: ROOM NO | F5: ROOM NAME | G5: Stage 1a Completion of Operator Inspection (Pre FFE) | H5: Stage 1b Completion of De-Snagging and close out operator Comments/Deep Cleaning | I5: Completion of FF&E installation | J5: Stage 2a Completion of Operator Inspection (Post FFE) | K5: Stage 2b Completion of De-Snagging /Sparkle Cleaning and handover | L5: Total Snag Raised | M5: Total Snag Open | N5: Total Snag Closed
D6: Level 06 - ALL DAY DINING, SPECIALITY RESTAURANT-2, CLUB LOUNGE, SUNSET BAR | E6: 06-001 | F6: GUEST LOBBY | G6: FALSE | H6: FALSE | I6: FALSE | J6: FALSE | K6: FALSE
D7: Level 06 - ALL DAY DINING, SPECIALITY RESTAURANT-2, CLUB LOUNGE, SUNSET BAR | E7: 06-003 | F7: GRAND CLUB LOUNGE SERVERY CATERING | G7: FALSE | H7: FALSE | I7: FALSE | J7: FALSE | K7: FALSE
D8: Level 06 - ALL DAY DINING, SPECIALITY RESTAURANT-2, CLUB LOUNGE, SUNSET BAR | E8: 06-005 | F8: PRIVATE TERRACE | G8: FALSE | H8: FALSE | I8: FALSE | J8: FALSE | K8: FALSE
D9: Level 06 - ALL DAY DINING, SPECIALITY RESTAURANT-2, CLUB LOUNGE, SUNSET BAR | E9: 06-006 | F9: GRAND CLUB LOUNGE PANTRY | G9: FALSE | H9: FALSE | I9: FALSE | J9: FALSE | K9: FALSE
D10: Level 06 - ALL DAY DINING, SPECIALITY RESTAURANT-2, CLUB LOUNGE, SUNSET BAR | E10: 06-007c | F10: ELEC. CL. | G10: FALSE | H10: FALSE | I10: FALSE | J10: FALSE | K10: FALSE
D11: Level 06 - ALL DAY DINING, SPECIALITY RESTAURANT-2, CLUB LOUNGE, SUNSET BAR | E11: 06-009 | F11: TOILET - FEMALE | G11: FALSE | H11: FALSE | I11: FALSE | J11: FALSE | K11: FALSE
D12: Level 06 - ALL DAY DINING, SPECIALITY RESTAURANT-2, CLUB LOUNGE, SUNSET BAR | E12: 06-011 | F12: TOILET-ADA | G12: FALSE | H12: FALSE | I12: FALSE | J12: FALSE | K12: FALSE
D13: Level 06 - ALL DAY DINING, SPECIALITY RESTAURANT-2, CLUB LOUNGE, SUNSET BAR | E13: 06-014a | F13: ELECTRICAL CABINET | G13: FALSE | H13: FALSE | I13: FALSE | J13: FALSE | K13: FALSE
D14: Level 06 - ALL DAY DINING, SPECIALITY RESTAURANT-2, CLUB LOUNGE, SUNSET BAR | E14: 06-016 | F14: DUMBWAITER | G14: FALSE | H14: FALSE | I14: FALSE | J14: FALSE | K14: FALSE
D15: Level 06 - ALL DAY DINING, SPECIALITY RESTAURANT-2, CLUB LOUNGE, SUNSET BAR | E15: 06-018 | F15: BEVERAGE COLD ROOM | G15: FALSE | H15: FALSE | I15: FALSE | J15: FALSE | K15: FALSE
D16: Level 06 - ALL DAY DINING, SPECIALITY RESTAURANT-2, CLUB LOUNGE, SUNSET BAR | E16: 06-020 | F16: WARE & GLASS WASH | G16: FALSE | H16: FALSE | I16: FALSE | J16: FALSE | K16: FALSE
D17: Level 06 - ALL DAY DINING, SPECIALITY RESTAURANT-2, CLUB LOUNGE, SUNSET BAR | E17: 06-022 | F17: SERVICE CORRIDOR | G17: FALSE | H17: FALSE | I17: FALSE | J17: FALSE | K17: FALSE
... D27: Level 06 - ALL DAY DINING, SPECIALITY RESTAURANT-2, CLUB LOUNGE, SUNSET BAR | E27: 06-037 | F27: CIRCULATION | G27: FALSE | H27: FALSE | I27: FALSE | J27: FALSE | K27: FALSE
L28: =SUM(L6:L27) -> 0 | M28: =SUM(M6:M27) -> 0 | N28: =SUM(N6:N27) -> 0

Sheet LEVEL 4, 5 & 6
B2: MENU
C7: SNAGGED DATE | D7: SNAGGED BY | E7: AREA Aconex name | F7: ROOM NO | G7: ROOM NAME | H7: Stage 1a Completion of Operator Inspection (Pre FFE) | I7: Stage 1b Completion of De-Snagging and close out operator Comments/Deep Cleaning | J7: Completion of FF&E installation | K7: Stage 2a Completion of Operator Inspection (Post FFE) | L7: Stage 2b Completion of De-Snagging /Sparkle Cleaning and handover | M7: Total Snag Raised | N7: Total Snag Open | O7: Total Snag Closed | S7: Arvind
E8: ALL DAY DINING, SPECIALITY RESTAURANT-2, CLUB LOUNGE, SUNSET BAR | F8: 04-006 | G8: GUEST STAIR - 06 | H8: FALSE | I8: FALSE | J8: FALSE | K8: FALSE | L8: FALSE
E9: ALL DAY DINING, SPECIALITY RESTAURANT-2, CLUB LOUNGE, SUNSET BAR | F9: 04-010 | G9: GUEST LOBBY | H9: FALSE | I9: FALSE | J9: FALSE | K9: FALSE | L9: FALSE
E10: ALL DAY DINING, SPECIALITY RESTAURANT-2, CLUB LOUNGE, SUNSET BAR | F10: 04-012 | G10: FEMALE TOILET | H10: FALSE | I10: FALSE | J10: FALSE | K10: FALSE | L10: FALSE
E11: ALL DAY DINING, SPECIALITY RESTAURANT-2, CLUB LOUNGE, SUNSET BAR | F11: 04-012b | G11: WC-1 | H11: FALSE | I11: FALSE | J11: FALSE | K11: FALSE | L11: FALSE
E12: ALL DAY DINING, SPECIALITY RESTAURANT-2, CLUB LOUNGE, SUNSET BAR | F12: 04-012d | G12: WC-3 | H12: FALSE | I12: FALSE | J12: FALSE | K12: FALSE | L12: FALSE
E13: ALL DAY DINING, SPECIALITY RESTAURANT-2, CLUB LOUNGE, SUNSET BAR | F13: 04-012f | G13: WC-5 | H13: FALSE | I13: FALSE | J13: FALSE | K13: FALSE | L13: FALSE
E14: ALL DAY DINING, SPECIALITY RESTAURANT-2, CLUB LOUNGE, SUNSET BAR | F14: 04-013 | G14: TOILET LOBBY | H14: FALSE | I14: FALSE | J14: FALSE | K14: FALSE | L14: FALSE
E15: ALL DAY DINING, SPECIALITY RESTAURANT-2, CLUB LOUNGE, SUNSET BAR | F15: 04-016a | G15: WC-1 | H15: FALSE | I15: FALSE | J15: FALSE | K15: FALSE | L15: FALSE
E16: ALL DAY DINING, SPECIALITY RESTAURANT-2, CLUB LOUNGE, SUNSET BAR | F16: 04-016c | G16: WC-3 | H16: FALSE | I16: FALSE | J16: FALSE | K16: FALSE | L16: FALSE
E17: ALL DAY DINING, SPECIALITY RESTAURANT-2, CLUB LOUNGE, SUNSET BAR | F17: 04-016e | G17: WC-5 | H17: FALSE | I17: FALSE | J17: FALSE | K17: FALSE | L17: FALSE
E18: ALL DAY DINING, SPECIALITY RESTAURANT-2, CLUB LOUNGE, SUNSET BAR | F18: 04-016g | G18: ADA- MALE TOILET | H18: FALSE | I18: FALSE | J18: FALSE | K18: FALSE | L18: FALSE
E19: ALL DAY DINING, SPECIALITY RESTAURANT-2, CLUB LOUNGE, SUNSET BAR | F19: 04-033 | G19: PREPARATION AREA | H19: FALSE | I19: FALSE | J19: FALSE | K19: FALSE | L19: FALSE
... E21: ALL DAY DINING, SPECIALITY RESTAURANT-2, CLUB LOUNGE, SUNSET BAR | F21: 04-047a | G21: F&B-2 PANTRY | H21: FALSE | I21: FALSE | J21: FALSE | K21: FALSE | L21: FALSE
M22: =SUM(M8:M21) -> 0 | N22: =SUM(N8:N21) -> 0 | O22: =SUM(O8:O21) -> 0

Sheet EMBERS
B2: MENU
C7: SNAGGED DATE | D7: SNAGGED BY | E7: AREA Aconex name | F7: ROOM NO | G7: ROOM NAME | H7: Stage 1a Completion of Operator Inspection (Pre FFE) | I7: Stage 1b Completion of De-Snagging and close out operator Comments/Deep Cleaning | J7: Completion of FF&E installation | K7: Stage 2a Completion of Operator Inspection (Post FFE) | L7: Stage 2b Completion of De-Snagging /Sparkle Cleaning and handover | M7: Total Snag Raised | N7: Total Snag Open | O7: Total Snag Closed | S7: Arvind

Sheet AMALFI POOL
B2: MENU
C7: SNAGGED DATE | D7: SNAGGED BY | E7: AREA Aconex name | F7: ROOM NO | G7: ROOM NAME | H7: Stage 1a Completion of Operator Inspection (Pre FFE) | I7: Stage 1b Completion of De-Snagging and close out operator Comments/Deep Cleaning | J7: Completion of FF&E installation | K7: Stage 2a Completion of Operator Inspection (Post FFE) | L7: Stage 2b Completion of De-Snagging /Sparkle Cleaning and handover | M7: Total Snag Raised | N7: Total Snag Open | O7: Total Snag Closed | S7: Arvind

Sheet RECREATION DRIFT POOLBAR & GRIL
B2: MENU
C7: SNAGGED DATE | D7: SNAGGED BY | E7: AREA Aconex name | F7: ROOM NO | G7: ROOM NAME | H7: Stage 1a Completion of Operator Inspection (Pre FFE) | I7: Stage 1b Completion of De-Snagging and close out operator Comments/Deep Cleaning | J7: Completion of FF&E installation | K7: Stage 2a Completion of Operator Inspection (Post FFE) | L7: Stage 2b Completion of De-Snagging /Sparkle Cleaning and handover | M7: Total Snag Raised | N7: Total Snag Open | O7: Total Snag Closed | S7: Arvind

Sheet SPA & Fitness
B2: MENU
C7: SNAGGED DATE | D7: SNAGGED BY | E7: AREA Aconex name | F7: ROOM NO | G7: ROOM NAME | H7: Stage 1a Completion of Operator Inspection (Pre FFE) | I7: Stage 1b Completion of De-Snagging and close out operator Comments/Deep Cleaning | J7: Completion of FF&E installation | K7: Stage 2a Completion of Operator Inspection (Post FFE) | L7: Stage 2b Completion of De-Snagging /Sparkle Cleaning and handover | M7: Total Snag Raised | N7: Total Snag Open | O7: Total Snag Closed | S7: Arvind
E8: FITNESS LEVEL | F8: 01-001 | G8: RECEPTION | H8: FALSE | I8: FALSE | J8: FALSE | K8: FALSE | L8: FALSE | S8: Thayalaraj
E9: FITNESS LEVEL | F9: 01-003 | G9: STORE | H9: FALSE | I9: FALSE | J9: FALSE | K9: FALSE | L9: FALSE | S9: Abdulrahman
E10: FITNESS LEVEL | F10: 01-005 | G10: CIRCULATION | H10: FALSE | I10: FALSE | J10: FALSE | K10: FALSE | L10: FALSE | S10: Naseer
E11: FITNESS LEVEL | F11: 01-007 | G11: MALE CHANGING | H11: FALSE | I11: FALSE | J11: FALSE | K11: FALSE | L11: FALSE | S11: M.Adel
E12: FITNESS LEVEL | F12: 01-009 | G12: TOILET | H12: FALSE | I12: FALSE | J12: FALSE | K12: FALSE | L12: FALSE | S12: Tarik
E13: FITNESS LEVEL | F13: 01-011 | G13: SHOWER | H13: FALSE | I13: FALSE | J13: FALSE | K13: FALSE | L13: FALSE | S13: Akram
E14: FITNESS LEVEL | F14: 01-013 | G14: W.C | H14: FALSE | I14: FALSE | J14: FALSE | K14: FALSE | L14: FALSE | S14: Prasanna
E15: FITNESS LEVEL | F15: 01-015 | G15: SHOWER | H15: FALSE | I15: FALSE | J15: FALSE | K15: FALSE | L15: FALSE | S15: Suresh
E16: FITNESS LEVEL | F16: 01-017 | G16: W.C | H16: FALSE | I16: FALSE | J16: FALSE | K16: FALSE | L16: FALSE | S16: Mosab
E17: FITNESS LEVEL | F17: 01-019 | G17: W.C | H17: FALSE | I17: FALSE | J17: FALSE | K17: FALSE | L17: FALSE | S17: Nawaf
E18: FITNESS LEVEL | F18: 01-021 | G18: FEMALE CHANGING | H18: FALSE | I18: FALSE | J18: FALSE | K18: FALSE | L18: FALSE | S18: Hafil
E19: FITNESS LEVEL | F19: 01-023 | G19: SHOWER | H19: FALSE | I19: FALSE | J19: FALSE | K19: FALSE | L19: FALSE | S19: Ibrar
... E22: FITNESS LEVEL | F22: 01-029 | G22: ELECTRICAL ROOM | H22: FALSE | I22: FALSE | J22: FALSE | K22: FALSE | L22: FALSE | S22: Simon Gonsalves
E23: FITNESS LEVEL | F23: 01-031 | G23: LAP POOL | H23: FALSE | I23: FALSE | J23: FALSE | K23: FALSE | L23: FALSE
E24: FITNESS LEVEL | F24: 01-033 | G24: CIRCULATION EXTERNAL | H24: FALSE | I24: FALSE | J24: FALSE | K24: FALSE | L24: FALSE
E25: FITNESS LEVEL | F25: 01-035 | G25: CARDIOVASCULAR EXERCISE | H25: FALSE | I25: FALSE | J25: FALSE | K25: FALSE | L25: FALSE
E26: FITNESS LEVEL | F26: 01-037 | G26: STRETCH/LOW IMPACT | H26: FALSE | I26: FALSE | J26: FALSE | K26: FALSE | L26: FALSE
E27: FITNESS LEVEL | F27: 01-039 | G27: AHU ROOM | H27: FALSE | I27: FALSE | J27: FALSE | K27: FALSE | L27: FALSE
E28: FITNESS LEVEL | F28: 01-041 | G28: ELV | H28: FALSE | I28: FALSE | J28: FALSE | K28: FALSE | L28: FALSE
E29: FITNESS LEVEL | F29: 01-043 | G29: CIRCULATION | H29: FALSE | I29: FALSE | J29: FALSE | K29: FALSE | L29: FALSE
E30: FITNESS LEVEL | F30: 01-045 | G30: OUTDOOR VITALITY POOL BALANCE TANK | H30: FALSE | I30: FALSE | J30: FALSE | K30: FALSE | L30: FALSE
E31: FITNESS LEVEL | F31: 01-047 | G31: VITALITY POOL L1 PLANT ROOM | H31: FALSE | I31: FALSE | J31: FALSE | K31: FALSE | L31: FALSE
E32: Level 02 - SPA | F32: 02-001 | G32: LOBBY | H32: FALSE | I32: FALSE | J32: FALSE | K32: FALSE | L32: FALSE
E33: Level 02 - SPA | F33: 02-003 | G33: LIFT | H33: FALSE | I33: FALSE | J33: FALSE | K33: FALSE | L33: FALSE
